<?xml version="1.0" ?>
<!-- =================================================================================== -->
<!-- |    This document was autogenerated by xacro from three_link_walker.xacro        | -->
<!-- |    EDITING THIS FILE BY HAND IS NOT RECOMMENDED                                 | -->
<!-- =================================================================================== -->
<robot name="three_link_walker" xmlns:xacro="http://ros.org/wiki/xacro">
  <link name="torso">
    <inertial>
      <origin rpy="0 0 0" xyz="0 0 0.1"/>
      <mass value="25"/>
      <inertia ixx="0" ixy="0" ixz="0" iyy="0" iyz="0" izz="0"/>
    </inertial>
    <visual>
      <origin rpy="0 0 0" xyz="0 0 0.25"/>
      <geometry>
        <cylinder length="0.5" radius="0.025"/>
      </geometry>
      <material name="black">
        <color rgba="0 0 0 1"/>
      </material>
    </visual>
  </link>
  <link name="right_leg">
    <inertial>
      <origin rpy="0 0 0" xyz="0 0 0.5"/>
      <mass value="5"/>
      <inertia ixx="0" ixy="0" ixz="0" iyy="0" iyz="0" izz="0"/>
    </inertial>
    <visual>
      <origin rpy="0 0 0" xyz="0 0 0.5"/>
      <geometry>
        <cylinder length="1.0" radius="0.025"/>
      </geometry>
      <material name="blue">
        <color rgba="0 0 1 1"/>
      </material>
    </visual> 
  </link>
  <link name="left_leg">
    <inertial>
      <origin rpy="0 0 0" xyz="0 0 0.5"/>
      <mass value="5"/>
      <inertia ixx="0" ixy="0" ixz="0" iyy="0" iyz="0" izz="0"/>
    </inertial>
    <visual>
      <origin rpy="0 0 0" xyz="0 0 0.5"/>
      <geometry>
        <cylinder length="1.0" radius="0.025"/>
      </geometry>
      <material name="red">
        <color rgba="1 0 0 1"/>
      </material>
    </visual>
  </link>
  <joint name="q_right" type="continuous">
    <origin rpy="0 0 0" xyz="0 0 0"/>
    <axis xyz="0 1 0"/>
    <parent link="torso"/>
    <child link="right_leg"/>
  </joint>
  <joint name="q_left" type="continuous">
    <origin rpy="0 0 0" xyz="0 0 0"/>
    <axis xyz="0 1 0"/>
    <parent link="torso"/>
    <child link="left_leg"/>
  </transmission>
  <transmission name="q_right_trans" type="pr2_mechanism_model/SimpleTransmission">
	<joint name="q_right"/>
	<actuator name="q_right_motor"/>
	<mechanicalReduction>1</mechanicalReduction>
	<motorInertia>0</motorInertia>
  </transmission>
  <transmission name="q_left_trans" type="pr2_mechanism_model/SimpleTransmission">
	<joint name="q_left"/>
	<actuator name="q_left_motor"/>
	<mechanicalReduction>1</mechanicalReduction>
	<motorInertia>0</motorInertia>
  </transmission>
</robot>
